Traceback (most recent call last):
  File "/opt/homebrew/lib/python3.11/site-packages/jupyter_cache/executors/utils.py", line 58, in single_nb_execution
    executenb(
  File "/opt/homebrew/lib/python3.11/site-packages/nbclient/client.py", line 1304, in execute
    return NotebookClient(nb=nb, resources=resources, km=km, **kwargs).execute()
           ^^^^^^^^^^^^^^^^^^^^^^^^^^^^^^^^^^^^^^^^^^^^^^^^^^^^^^^^^^^^^^^^^^^^^
  File "/Users/lex/Library/Python/3.11/lib/python/site-packages/jupyter_core/utils/__init__.py", line 166, in wrapped
    return loop.run_until_complete(inner)
           ^^^^^^^^^^^^^^^^^^^^^^^^^^^^^^
  File "/opt/homebrew/Cellar/python@3.11/3.11.4/Frameworks/Python.framework/Versions/3.11/lib/python3.11/asyncio/base_events.py", line 653, in run_until_complete
    return future.result()
           ^^^^^^^^^^^^^^^
  File "/opt/homebrew/lib/python3.11/site-packages/nbclient/client.py", line 705, in async_execute
    await self.async_execute_cell(
  File "/opt/homebrew/lib/python3.11/site-packages/nbclient/client.py", line 1020, in async_execute_cell
    await self._check_raise_for_error(cell, cell_index, exec_reply)
  File "/opt/homebrew/lib/python3.11/site-packages/nbclient/client.py", line 914, in _check_raise_for_error
    raise CellExecutionError.from_cell_and_msg(cell, exec_reply_content)
nbclient.exceptions.CellExecutionError: An error occurred while executing the following cell:
------------------
dataset2 = dataset.copy()
dataset2['Gross national income (GNI) per capita'].replace('..', '1', inplace=True)
dataset2['Gross national income (GNI) per capita'] = pd.to_numeric(dataset['Gross national income (GNI) per capita'])

# Create the line plot for GNI and HDI
fig_hdi = px.scatter(dataset2, x="Gross national income (GNI) per capita", y="Human Development Index (HDI) ", trendline="lowess")
fig_tons = px.scatter(dataset2, x="Gross national income (GNI) per capita", y="TonsPerCapita", trendline="lowess")

fig_hdi.show()
fig_tons.show()
------------------

[0;31m---------------------------------------------------------------------------[0m
[0;31mValueError[0m                                Traceback (most recent call last)
File [0;32m/opt/homebrew/lib/python3.11/site-packages/pandas/_libs/lib.pyx:2280[0m, in [0;36mpandas._libs.lib.maybe_convert_numeric[0;34m()[0m

[0;31mValueError[0m: Unable to parse string ".."

During handling of the above exception, another exception occurred:

[0;31mValueError[0m                                Traceback (most recent call last)
Cell [0;32mIn[6], line 3[0m
[1;32m      1[0m dataset2 [38;5;241m=[39m dataset[38;5;241m.[39mcopy()
[1;32m      2[0m dataset2[[38;5;124m'[39m[38;5;124mGross national income (GNI) per capita[39m[38;5;124m'[39m][38;5;241m.[39mreplace([38;5;124m'[39m[38;5;124m..[39m[38;5;124m'[39m, [38;5;124m'[39m[38;5;124m1[39m[38;5;124m'[39m, inplace[38;5;241m=[39m[38;5;28;01mTrue[39;00m)
[0;32m----> 3[0m dataset2[[38;5;124m'[39m[38;5;124mGross national income (GNI) per capita[39m[38;5;124m'[39m] [38;5;241m=[39m [43mpd[49m[38;5;241;43m.[39;49m[43mto_numeric[49m[43m([49m[43mdataset[49m[43m[[49m[38;5;124;43m'[39;49m[38;5;124;43mGross national income (GNI) per capita[39;49m[38;5;124;43m'[39;49m[43m][49m[43m)[49m
[1;32m      5[0m [38;5;66;03m# Create the line plot for GNI and HDI[39;00m
[1;32m      6[0m fig_hdi [38;5;241m=[39m px[38;5;241m.[39mscatter(dataset2, x[38;5;241m=[39m[38;5;124m"[39m[38;5;124mGross national income (GNI) per capita[39m[38;5;124m"[39m, y[38;5;241m=[39m[38;5;124m"[39m[38;5;124mHuman Development Index (HDI) [39m[38;5;124m"[39m, trendline[38;5;241m=[39m[38;5;124m"[39m[38;5;124mlowess[39m[38;5;124m"[39m)

File [0;32m/opt/homebrew/lib/python3.11/site-packages/pandas/core/tools/numeric.py:217[0m, in [0;36mto_numeric[0;34m(arg, errors, downcast, dtype_backend)[0m
[1;32m    215[0m coerce_numeric [38;5;241m=[39m errors [38;5;129;01mnot[39;00m [38;5;129;01min[39;00m ([38;5;124m"[39m[38;5;124mignore[39m[38;5;124m"[39m, [38;5;124m"[39m[38;5;124mraise[39m[38;5;124m"[39m)
[1;32m    216[0m [38;5;28;01mtry[39;00m:
[0;32m--> 217[0m     values, new_mask [38;5;241m=[39m [43mlib[49m[38;5;241;43m.[39;49m[43mmaybe_convert_numeric[49m[43m([49m[43m  [49m[38;5;66;43;03m# type: ignore[call-overload]  # noqa[39;49;00m
[1;32m    218[0m [43m        [49m[43mvalues[49m[43m,[49m
[1;32m    219[0m [43m        [49m[38;5;28;43mset[39;49m[43m([49m[43m)[49m[43m,[49m
[1;32m    220[0m [43m        [49m[43mcoerce_numeric[49m[38;5;241;43m=[39;49m[43mcoerce_numeric[49m[43m,[49m
[1;32m    221[0m [43m        [49m[43mconvert_to_masked_nullable[49m[38;5;241;43m=[39;49m[43mdtype_backend[49m[43m [49m[38;5;129;43;01mis[39;49;00m[43m [49m[38;5;129;43;01mnot[39;49;00m[43m [49m[43mlib[49m[38;5;241;43m.[39;49m[43mno_default[49m
[1;32m    222[0m [43m        [49m[38;5;129;43;01mor[39;49;00m[43m [49m[38;5;28;43misinstance[39;49m[43m([49m[43mvalues_dtype[49m[43m,[49m[43m [49m[43mStringDtype[49m[43m)[49m[43m,[49m
[1;32m    223[0m [43m    [49m[43m)[49m
[1;32m    224[0m [38;5;28;01mexcept[39;00m ([38;5;167;01mValueError[39;00m, [38;5;167;01mTypeError[39;00m):
[1;32m    225[0m     [38;5;28;01mif[39;00m errors [38;5;241m==[39m [38;5;124m"[39m[38;5;124mraise[39m[38;5;124m"[39m:

File [0;32m/opt/homebrew/lib/python3.11/site-packages/pandas/_libs/lib.pyx:2322[0m, in [0;36mpandas._libs.lib.maybe_convert_numeric[0;34m()[0m

[0;31mValueError[0m: Unable to parse string ".." at position 178
ValueError: Unable to parse string ".." at position 178

